<?xml version="1.0" encoding="utf-8"?>
<!-- This URDF was automatically created by SolidWorks to URDF Exporter! Originally created by Stephen Brawner (brawner@gmail.com) 
     Commit Version: 1.6.0-1-g15f4949  Build Version: 1.6.7594.29634
     For more information, please see http://wiki.ros.org/sw_urdf_exporter -->
<robot
  name="car_pkg">
  <material
    name="rubber">
    <color
      rgba="0.2 0.2 0.2 1" />
  </material>
  <material
    name="red_metal">
    <color
      rgba="0.8 0.2 0.2 1" />
  </material>
  <link
    name="dummy_link">
  </link>
  <joint
    name="dummy_joint" type="fixed">
    <parent
      link="dummy_link" />
    <child
      link="base_link" />
  </joint>
  <link
    name="base_link">
    <inertial>
      <origin
        xyz="0.0424709579323588 0.141492510044649 2.27297672583814E-17"
        rpy="0 0 0" />
      <mass
        value="47.9977829804329" />
      <inertia
        ixx="1.37865067310813"
        ixy="-0.852319927205702"
        ixz="1.3813209492185E-16"
        iyy="3.52490374117594"
        iyz="4.80259459580282E-18"
        izz="3.16096143698967" />
    </inertial>
    <visual>
      <origin
        xyz="0 0 0"
        rpy="0 0 0" />
      <geometry>
        <mesh
          filename="package://car_pkg/meshes/base_link.STL" />
      </geometry>
      <material name="red_metal"/>
    </visual>
    <collision>
      <origin
        xyz="0 0 0"
        rpy="0 0 0" />
      <geometry>
        <mesh
          filename="package://car_pkg/meshes/base_link.STL" />
      </geometry>
    </collision>
  </link>
  <link
    name="rear_axle">
    <inertial>
      <origin
        xyz="-9.87520524763014E-17 -5.55111512312578E-17 6.93889390390723E-18"
        rpy="0 0 0" />
      <mass
        value="0.218796289474299" />
      <inertia
        ixx="1.76448267646549E-05"
        ixy="1.53412958881235E-18"
        ixz="-7.28417088826858E-19"
        iyy="0.00340839237003917"
        iyz="2.1160189804569E-35"
        izz="0.00340839237003917" />
    </inertial>
    <visual>
      <origin
        xyz="0 0 0"
        rpy="0 0 0" />
      <geometry>
        <mesh
          filename="package://car_pkg/meshes/rear_axle.STL" />
      </geometry>
      <material
        name="">
        <color
          rgba="0.792156862745098 0.819607843137255 0.933333333333333 1" />
      </material>
    </visual>
    <collision>
      <origin
        xyz="0 0 0"
        rpy="0 0 0" />
      <geometry>
        <mesh
          filename="package://car_pkg/meshes/rear_axle.STL" />
      </geometry>
    </collision>
  </link>
  <joint
    name="rear_joint"
    type="continuous">
    <origin
      xyz="-0.2286 0 0.0508"
      rpy="-2.8204 0 1.5708" />
    <parent
      link="base_link" />
    <child
      link="rear_axle" />
    <axis
      xyz="1 0 0" />
    <limit
      effort="1000"
      velocity="1000" />
  </joint>
  <transmission name="rear_trans">
    <type>transmission_interface/SimpleTransmission</type>
    <joint name="rear_joint">
      <hardwareInterface>hardware_interface/VelocityJointInterface</hardwareInterface>
    </joint>
    <actuator name="rear_motor">
      <mechanicalReduction>1</mechanicalReduction>
    </actuator>
  </transmission>
  <link
    name="r_rear_wheel">
    <inertial>
      <origin
        xyz="0.0382499999999987 -3.46944695195361E-17 2.58126853225349E-15"
        rpy="0 0 0" />
      <mass
        value="2.45180547910906" />
      <inertia
        ixx="0.0127525390614078"
        ixy="1.86302887689269E-35"
        ixz="5.43621548791774E-17"
        iyy="0.00756256948225711"
        iyz="2.06756332028389E-37"
        izz="0.00756256948225711" />
    </inertial>
    <visual>
      <origin
        xyz="0.07 -0.1 -0.1"
        rpy="0 -1.56 0" />
      <geometry>
        <mesh
          filename="package://car_pkg/meshes/visual_tyre.STL" scale="0.001 0.001 0.001"/>
      </geometry>
      <material name="rubber"/>
    </visual>
    <collision>
      <origin
        xyz="0 0 0"
        rpy="0 0 0" />
      <geometry>
        <mesh
          filename="package://car_pkg/meshes/r_rear_wheel.STL" />
      </geometry>
    </collision>
  </link>
  <joint
    name="r_rear_joint"
    type="fixed">
    <origin
      xyz="-0.1778 0 0"
      rpy="1.892 0 3.1416" />
    <parent
      link="rear_axle" />
    <child
      link="r_rear_wheel" />
    <axis
      xyz="0 0 0" />
  </joint>
  <link
    name="l_rear_wheel">
    <inertial>
      <origin
        xyz="0.03825 6.93889390390723E-17 4.24660306919122E-15"
        rpy="0 0 0" />
      <mass
        value="2.45180547910906" />
      <inertia
        ixx="0.0127525390614078"
        ixy="-5.84073755564824E-35"
        ixz="-1.79349284331023E-17"
        iyy="0.00756256948225711"
        iyz="1.3978411939278E-35"
        izz="0.00756256948225711" />
    </inertial>
    <visual>
      <origin
        xyz="0.07 -0.1 -0.1"
        rpy="0 -1.56 0" />
      <geometry>
        <mesh
          filename="package://car_pkg/meshes/visual_tyre.STL" scale="0.001 0.001 0.001"/>
      </geometry>
      <material name="rubber"/>
    </visual>
    <collision>
      <origin
        xyz="0 0 0"
        rpy="0 0 0" />
      <geometry>
        <mesh
          filename="package://car_pkg/meshes/l_rear_wheel.STL" />
      </geometry>
    </collision>
  </link>
  <joint
    name="l_rear_joint"
    type="fixed">
    <origin
      xyz="0.1778 0 0"
      rpy="-1.892 0 0" />
    <parent
      link="rear_axle" />
    <child
      link="l_rear_wheel" />
    <axis
      xyz="0 0 0" />
  </joint>
  <link
    name="left_axle">
    <inertial>
      <origin
        xyz="0.0388634709790775 4.44089209850063E-16 -0.101740086144568"
        rpy="0 0 0" />
      <mass
        value="0.154885786948962" />
      <inertia
        ixx="0.00066373237899345"
        ixy="7.75674967024387E-19"
        ixz="-0.000115977221210615"
        iyy="0.000767589430522454"
        iyz="8.92592992650556E-19"
        izz="0.000116347815817503" />
    </inertial>
    <visual>
      <origin
        xyz="0 0 0"
        rpy="0 0 0" />
      <geometry>
        <mesh
          filename="package://car_pkg/meshes/left_axle.STL" />
      </geometry>
      <material
        name="">
        <color
          rgba="0.792156862745098 0.819607843137255 0.933333333333333 1" />
      </material>
    </visual>
    <collision>
      <origin
        xyz="0 0 0"
        rpy="0 0 0" />
      <geometry>
        <mesh
          filename="package://car_pkg/meshes/left_axle.STL" />
      </geometry>
    </collision>
  </link>
  <joint
    name="left_joint"
    type="revolute">
    <origin
      xyz="0.2794 0.2159 0.0381"
      rpy="-3.1416 0 -1.5708" />
    <parent
      link="base_link" />
    <child
      link="left_axle" />
    <axis
      xyz="0 0 1" />
    <limit
      lower="-1.0"
      upper="1.0"
      effort="1000"
      velocity="10" />
  </joint>
  <transmission name="front_left_steering">
    <type>transmission_interface/SimpleTransmission</type>
    <joint name="left_joint">
      <hardwareInterface>hardware_interface/PositionJointInterface</hardwareInterface>
    </joint>
    <actuator name="front_left_steer">
      <mechanicalReduction>1</mechanicalReduction>
    </actuator>
  </transmission>
  <link
    name="l_front_wheel">
    <inertial>
      <origin
        xyz="0.00014999999999904 -5.48866507799062E-15 1.49880108324396E-15"
        rpy="0 0 0" />
      <mass
        value="2.45180547910906" />
      <inertia
        ixx="0.0127525390614078"
        ixy="2.35098870164458E-35"
        ixz="-1.79392745163191E-17"
        iyy="0.00756256948225711"
        iyz="-1.26533746661757E-35"
        izz="0.00756256948225711" />
    </inertial>
    <visual>
      <origin
        xyz="0.04 -0.1 -0.1"
        rpy="0 -1.56 0" />
      <geometry>
        <mesh
          filename="package://car_pkg/meshes/visual_tyre.STL" scale="0.001 0.001 0.001"/>
      </geometry>
      <material name="rubber"/>
    </visual>
    <collision>
      <origin
        xyz="0 0 0"
        rpy="0 0 0" />
      <geometry>
        <mesh
          filename="package://car_pkg/meshes/l_front_wheel.STL" />
      </geometry>
    </collision>
  </link>
  <joint
    name="l_front_joint"
    type="continuous">
    <origin
      xyz="0 0 -0.0127"
      rpy="-1.5708 0 3.1416" />
    <parent
      link="left_axle" />
    <child
      link="l_front_wheel" />
    <axis
      xyz="1 0 0" />
  </joint>
  <link
    name="right_axle">
    <inertial>
      <origin
        xyz="0.038863470979077 9.99200722162641E-16 0.101740086144568"
        rpy="0 0 0" />
      <mass
        value="0.154885786948962" />
      <inertia
        ixx="0.00066373237899345"
        ixy="9.09713385351119E-19"
        ixz="0.000115977221210617"
        iyy="0.000767589430522455"
        iyz="-5.64228176111916E-18"
        izz="0.000116347815817504" />
    </inertial>
    <visual>
      <origin
        xyz="0 0 0"
        rpy="0 0 0" />
      <geometry>
        <mesh
          filename="package://car_pkg/meshes/right_axle.STL" />
      </geometry>
      <material
        name="">
        <color
          rgba="0.792156862745098 0.819607843137255 0.933333333333333 1" />
      </material>
    </visual>
    <collision>
      <origin
        xyz="0 0 0"
        rpy="0 0 0" />
      <geometry>
        <mesh
          filename="package://car_pkg/meshes/right_axle.STL" />
      </geometry>
    </collision>
  </link>
  <joint
    name="right_joint"
    type="revolute">
    <origin
      xyz="0.2794 -0.2159 0.0381"
      rpy="0 0 1.5562" />
    <parent
      link="base_link" />
    <child
      link="right_axle" />
    <axis
      xyz="0 0 1" />
    <limit
      lower="-1.0"
      upper="1.0"
      effort="1000"
      velocity="1" />
  </joint>
  <transmission name="front_right_steering">
    <type>transmission_interface/SimpleTransmission</type>
    <joint name="right_joint">
      <hardwareInterface>hardware_interface/PositionJointInterface</hardwareInterface>
    </joint>
    <actuator name="front_right_steer">
      <mechanicalReduction>1</mechanicalReduction>
    </actuator>
  </transmission>
  <link
    name="r_front_wheel">
    <inertial>
      <origin
        xyz="0.000149999999999928 -6.93889390390723E-18 0"
        rpy="0 0 0" />
      <mass
        value="2.45180547910906" />
      <inertia
        ixx="0.0127525390614078"
        ixy="1.86643709927485E-18"
        ixz="6.32157629194829E-17"
        iyy="0.00756256948225712"
        iyz="1.46182666572821E-19"
        izz="0.00756256948225712" />
    </inertial>
    <visual>
      <origin
        xyz="0.04 -0.1 -0.1"
        rpy="0 -1.56 0" />
      <geometry>
        <mesh
          filename="package://car_pkg/meshes/visual_tyre.STL" scale="0.001 0.001 0.001"/>
      </geometry>
      <material name="rubber"/>
    </visual>
    <collision>
      <origin
        xyz="0 0 0"
        rpy="0 0 0" />
      <geometry>
        <mesh
          filename="package://car_pkg/meshes/r_front_wheel.STL" />
      </geometry>
    </collision>
  </link>
  <joint
    name="r_front_joint"
    type="continuous">
    <origin
      xyz="0 0 0.0127"
      rpy="1.6035 0 -3.1416" />
    <parent
      link="right_axle" />
    <child
      link="r_front_wheel" />
    <axis
      xyz="1 0 0" />
  </joint>
</robot>